<?xml version="1.0" ?>
<robot name="kuka_kr8_r2010">

<!-- KINEMATIC PROPERTIES -->
<joint name="world_joint" type="fixed">
  <parent link="world" />
  <child link="base" />
  <!-- <origin rpy="0.0 0.0 3.926990817" xyz="3.0 3.0 0.0" />-->
  <origin rpy="0.0 0.0 0.0" xyz="0 0 0" />
</joint>
<joint name="joint1" type="continuous">
  <parent link="base" />
  <child link="link1" />
  <origin rpy="0.0 0.0 0.0" xyz="0.0 0.0 0.520" />
  <axis xyz="0 0 -1" />
</joint>
<joint name="joint2" type="continuous">
  <parent link="link1" />
  <child link="link2" />
  <origin rpy="0.0 0.0 0.0" xyz="0.160 0.0 0.0" />
  <axis xyz="0 1 0" />
</joint>
<joint name="joint3" type="continuous">
  <parent link="link2" />
  <child link="link3" />
  <origin rpy="0.0 0.0 0.0" xyz="0.0 0.0 0.980" />
  <axis xyz="0 1 0" />
</joint>
<joint name="joint4" type="continuous">
  <parent link="link3" />
  <child link="link4" />
  <origin rpy="0.0 0.0 0.0" xyz="0.0 0.0 0.150" />
  <axis xyz="-1 0 0" />
</joint>
<joint name="joint5" type="continuous">
  <parent link="link4" />
  <child link="link5" />
  <origin rpy="0.0 0.0 0.0" xyz="0.860 0.0 0.0" />
  <axis xyz="0 1 0" />
</joint>
<joint name="joint6" type="continuous">
  <parent link="link5" />
  <child link="link6" />
  <origin rpy="0.0 0.0 0.0" xyz="0.0 0.0 0.0" />
  <axis xyz="-1 0 0" />
</joint>
<joint name="ee_joint" type="fixed">
  <parent link="link6" />
  <child link="ee" />
  <origin rpy="0.0 0.0 0.0" xyz="0.153 0.0 0.0" />
</joint>

<!-- INERTIAL PROPERTIES -->
<link name="world" />
<link name="base">
  <visual>
    <origin xyz="0.0 0 0" rpy="0.0 0.0 0.0" />
    <geometry>
      <cylinder radius="0.3" length="0.26" />
    </geometry>
    <material name="mat1">
      <color rgba="0 1.0 0 0" />
    </material>
  </visual>
</link>
<link name="link1">
  <visual>
    <origin xyz="0.06 0 -0.26" rpy="0.0 0.0 0.0" />
    <geometry>
      <cylinder radius="0.1" length="0.520" />
    </geometry>
    <material name="mat1">
      <color rgba="0 1.0 0 0" />
    </material>
  </visual>
</link>
<link name="link2">
  <visual>
    <origin xyz="0.0 0.0 0.490" rpy="0.0 0.0 0.0" />
    <geometry>
      <cylinder radius="0.0750" length="0.980" />
    </geometry>
    <material name="mat2">
      <color rgba="0 0 1.0 0" />
    </material>
  </visual>
</link>
<link name="link3">
  <visual>
    <origin xyz="0.430 0.0 0.150" rpy="0.0 1.570796327 0.0" />
    <geometry>
      <cylinder radius="0.0750" length="0.860" />
    </geometry>
    <material name="mat3">
      <color rgba="1.0 0 0 0" />
    </material>
  </visual>
</link>
<link name="link4" />
<link name="link5" />
<link name="link6">
  <visual>
    <origin xyz="0.0765 0.0 0.0" rpy="0.0 1.570796327 0.0" />
    <geometry>
      <cylinder radius="0.020" length="0.153" />
    </geometry>
    <material name="mat4">
      <color rgba="0 1.0 1.0 1.0" />
    </material>
  </visual>
</link>
<link name="ee" />
</robot>