<?xml version="1.0" ?>
<robot name="kuka_kr8_r2010">

<!-- KINEMATIC PROPERTIES -->
<joint name="world_joint" type="fixed">
  <parent link="world" />
  <child link="base" />
  <origin rpy="0.0 0.0 0.7853981634" xyz="-3.0 -3.0 0.0" />
</joint>
<joint name="joint1" type="continuous">
  <parent link="base" />
  <child link="link1" />
  <origin rpy="0.0 0.0 0.0" xyz="0.0 0.0 0.520" />
  <axis xyz="0 0 -1" />
</joint>
<joint name="joint2" type="continuous">
  <parent link="link1" />
  <child link="link2" />
  <origin rpy="0.0 0.0 0.0" xyz="0.160 0.0 0.0" />
  <axis xyz="0 1 0" />
</joint>
<joint name="joint3" type="continuous">
  <parent link="link2" />
  <child link="link3" />
  <origin rpy="0.0 0.0 0.0" xyz="0.0 0.0 0.980" />
  <axis xyz="0 1 0" />
</joint>
<joint name="joint4" type="continuous">
  <parent link="link3" />
  <child link="link4" />
  <origin rpy="0.0 0.0 0.0" xyz="0.0 0.0 0.150" />
  <axis xyz="-1 0 0" />
</joint>
<joint name="joint5" type="continuous">
  <parent link="link4" />
  <child link="link5" />
  <origin rpy="0.0 0.0 0.0" xyz="0.860 0.0 0.0" />
  <axis xyz="0 1 0" />
</joint>
<joint name="joint6" type="continuous">
  <parent link="link5" />
  <child link="link6" />
  <origin rpy="0.0 0.0 0.0" xyz="0.0 0.0 0.0" />
  <axis xyz="-1 0 0" />
</joint>
<joint name="ee_joint" type="fixed">
  <parent link="link6" />
  <child link="ee" />
  <origin rpy="0.0 0.0 0.0" xyz="0.153 0.0 0.0" />
</joint>

<!-- INERTIAL PROPERTIES -->
<link name="world" />
<link name="base" />
<link name="link1">
  <inertial>
    <mass value="40.0" />
    <origin rpy="0.0 0.0 0.0" xyz="0.06 0.0 -0.13" />
    <inertia ixx="0.32533" ixy="0.0" ixz="0.0" iyy="0.32533" iyz="0.0" izz="0.2" />
  </inertial>
</link>
<link name="link2">
  <inertial>
    <mass value="40.0" />
    <origin rpy="0.0 0.0 0.0" xyz="0.0 0.0 0.49" />
    <inertia ixx="3.258" ixy="0.0" ixz="0.0" iyy="3.258" iyz="0.0" izz="0.1125" />
  </inertial>
</link>
<link name="link3">
  <inertial>
    <mass value="40.0" />
    <origin rpy="0.0 0.0 0.0" xyz="0.4 0.0 0.15" />
    <inertia ixx="0.1125" ixy="0.0" ixz="0.0" iyy="2.1896" iyz="0.0" izz="2.1896" />
  </inertial>
</link>
<link name="link4">
  <inertial>
    <mass value="5.0" />
    <origin rpy="0.0 0.0 0.0" xyz="0.83 0.0 0.0" />
    <inertia ixx="0.01406" ixy="0.0" ixz="0.0" iyy="0.0085313" iyz="0.0" izz="0.0085313" />
  </inertial>
</link>
<link name="link5">
  <inertial>
    <mass value="0.0" />
    <origin rpy="0.0 0.0 0.0" xyz="0.0 0.0 0.0" />
    <inertia ixx="0.0" ixy="0.0" ixz="0.0" iyy="0.0" iyz="0.0" izz="0.0" />
  </inertial>
</link>
<link name="link6">
  <inertial>
    <mass value="3.0" />
    <origin rpy="0.0 0.0 0.0" xyz="0.077 0.0 0.0" />
    <inertia ixx="0.0006" ixy="0.0" ixz="0.0" iyy="0.006152" iyz="0.0" izz="0.006152" />
  </inertial>
</link>
<link name="ee" />
</robot>
