<?xml version="1.0" ?>
<robot name="kuka_kr8_r2010">

<!-- KINEMATIC PROPERTIES -->
<joint name="world_joint" type="fixed">
  <parent link="world" />
  <child link="base" />
  <origin rpy="0.0 0.0 0.7853981634" xyz="-3.0 -3.0 0.0" />
</joint>
<joint name="joint1" type="continuous">
  <parent link="base" />
  <child link="link1" />
  <origin rpy="0.0 0.0 0.0" xyz="0.0 0.0 0.520" />
  <axis xyz="0 0 -1" />
</joint>
<joint name="joint2" type="continuous">
  <parent link="link1" />
  <child link="link2" />
  <origin rpy="0.0 0.0 0.0" xyz="0.160 0.0 0.0" />
  <axis xyz="0 1 0" />
</joint>
<joint name="joint3" type="continuous">
  <parent link="link2" />
  <child link="link3" />
  <origin rpy="0.0 0.0 0.0" xyz="0.0 0.0 0.980" />
  <axis xyz="0 1 0" />
</joint>
<joint name="joint4" type="continuous">
  <parent link="link3" />
  <child link="link4" />
  <origin rpy="0.0 0.0 0.0" xyz="0.0 0.0 0.150" />
  <axis xyz="-1 0 0" />
</joint>
<joint name="joint5" type="continuous">
  <parent link="link4" />
  <child link="link5" />
  <origin rpy="0.0 0.0 0.0" xyz="0.860 0.0 0.0" />
  <axis xyz="0 1 0" />
</joint>
<joint name="joint6" type="continuous">
  <parent link="link5" />
  <child link="link6" />
  <origin rpy="0.0 0.0 0.0" xyz="0.0 0.0 0.0" />
  <axis xyz="-1 0 0" />
</joint>
<joint name="ee_joint" type="fixed">
  <parent link="link6" />
  <child link="ee" />
  <origin rpy="0.0 0.0 0.0" xyz="0.153 0.0 0.0" />
</joint>

<!-- INERTIAL PROPERTIES -->
<link name="world" />
<link name="base" />
<link name="link1">
</link>
<link name="link2">
</link>
<link name="link3">
</link>
<link name="link4">
</link>
<link name="link5">
</link>
<link name="link6">
</link>
<link name="ee">
  <inertial>
    <mass value="1.0" />
    <origin rpy="0.0 0.0 0.0" xyz="0.0 0.0 0.0" />
    <inertia ixx="0.0" ixy="0.0" ixz="0.0" iyy="0.0" iyz="0.0" izz="0.0" />
  </inertial>
</link>
</robot>